Workbook

Sheet Summary
A1: Progress summary
A2: All counts are formulas reading the Checklist sheet. Update Status, Owner and Due date there.
A3: Last updated (enter by hand) | B3: 46284
A5: Status | B5: Items
A6: Not started | B6: =COUNTIF(Checklist!$L$7:$L$73,A6) -> 67
A7: In progress | B7: =COUNTIF(Checklist!$L$7:$L$73,A7) -> 0
A8: Blocked | B8: =COUNTIF(Checklist!$L$7:$L$73,A8) -> 0
A9: Done | B9: =COUNTIF(Checklist!$L$7:$L$73,A9) -> 0
A10: Total items | B10: =SUM(B6:B9) -> 67
A11: % done | B11: =IF(B10=0,0,B9/B10) -> 0
A13: Needs attention | B13: Items
A14: Open items with no owner | B14: =SUMPRODUCT((Checklist!$J$7:$J$73="")*(Checklist!$L$7:$L$73<>"Done")) -> 67
A15: Open High-priority items with no owner | B15: =SUMPRODUCT((Checklist!$J$7:$J$73="")*(Checklist!$L$7:$L$73<>"Done")*(Checklist!$B$7:$B$73="High")) -> 27
A16: Open items past their due date | B16: =SUMPRODUCT((Checklist!$K$7:$K$73<>"")*(Checklist!$K$7:$K$73<TODAY())*(Checklist!$L$7:$L$73<>"Done")) -> 0
A17: Blocked items | B17: =COUNTIF(Checklist!$L$7:$L$73,"Blocked") -> 0
A19: Priority | B19: Items | C19: Done | D19: % done
A20: High | B20: =COUNTIF(Checklist!$B$7:$B$73,A20) -> 27 | C20: =COUNTIFS(Checklist!$B$7:$B$73,A20,Checklist!$L$7:$L$73,"Done") -> 0 | D20: =IF(B20=0,0,C20/B20) -> 0
A21: Medium | B21: =COUNTIF(Checklist!$B$7:$B$73,A21) -> 30 | C21: =COUNTIFS(Checklist!$B$7:$B$73,A21,Checklist!$L$7:$L$73,"Done") -> 0 | D21: =IF(B21=0,0,C21/B21) -> 0
A22: Low | B22: =COUNTIF(Checklist!$B$7:$B$73,A22) -> 10 | C22: =COUNTIFS(Checklist!$B$7:$B$73,A22,Checklist!$L$7:$L$73,"Done") -> 0 | D22: =IF(B22=0,0,C22/B22) -> 0
A25: Work batch | B25: Items | C25: Done | D25: % done | E25: Goal
A26: Batch 1 - Verify & set up | B26: =COUNTIF(Checklist!$C$7:$C$73,A26) -> 13 | C26: =COUNTIFS(Checklist!$C$7:$C$73,A26,Checklist!$L$7:$L$73,"Done") -> 0 | D26: =IF(B26=0,0,C26/B26) -> 0 | E26: Free checks and setup that need no site edits. Do these first so you have a baseline (including the AI-citation test) before anything changes.
A27: Batch 2 - Fix accuracy & credentials | B27: =COUNTIF(Checklist!$C$7:$C$73,A27) -> 16 | C27: =COUNTIFS(Checklist!$C$7:$C$73,A27,Checklist!$L$7:$L$73,"Done") -> 0 | D27: =IF(B27=0,0,C27/B27) -> 0 | E27: Resolve contradictions, correct overreaching claims, update Privacy. Needs owner decisions and a lawyer review; blocks most later work.
A28: Batch 3 - Homepage & site fixes | B28: =COUNTIF(Checklist!$C$7:$C$73,A28) -> 15 | C28: =COUNTIFS(Checklist!$C$7:$C$73,A28,Checklist!$L$7:$L$73,"Done") -> 0 | D28: =IF(B28=0,0,C28/B28) -> 0 | E28: Homepage on-page fixes and sitewide clean-up, once the facts are settled in Batch 2.
A29: Batch 4 - New pages | B29: =COUNTIF(Checklist!$C$7:$C$73,A29) -> 14 | C29: =COUNTIFS(Checklist!$C$7:$C$73,A29,Checklist!$L$7:$L$73,"Done") -> 0 | D29: =IF(B29=0,0,C29/B29) -> 0 | E29: Build the new pages, then link them from the homepage and update the sitemap.
A30: Batch 5 - Structured data | B30: =COUNTIF(Checklist!$C$7:$C$73,A30) -> 5 | C30: =COUNTIFS(Checklist!$C$7:$C$73,A30,Checklist!$L$7:$L$73,"Done") -> 0 | D30: =IF(B30=0,0,C30/B30) -> 0 | E30: Structured data, after the visible text is final so the markup matches the page.
A31: Batch 6 - Evidence & ongoing | B31: =COUNTIF(Checklist!$C$7:$C$73,A31) -> 4 | C31: =COUNTIFS(Checklist!$C$7:$C$73,A31,Checklist!$L$7:$L$73,"Done") -> 0 | D31: =IF(B31=0,0,C31/B31) -> 0 | E31: Ongoing: testimonials, bio details, real examples, PDF regeneration if needed.
A33: Section | B33: Items | C33: Done | D33: % done
A34: A. Accuracy & consistency | B34: =COUNTIF(Checklist!$D$7:$D$73,A34) -> 17 | C34: =COUNTIFS(Checklist!$D$7:$D$73,A34,Checklist!$L$7:$L$73,"Done") -> 0 | D34: =IF(B34=0,0,C34/B34) -> 0
A35: B. New pages & structure | B35: =COUNTIF(Checklist!$D$7:$D$73,A35) -> 12 | C35: =COUNTIFS(Checklist!$D$7:$D$73,A35,Checklist!$L$7:$L$73,"Done") -> 0 | D35: =IF(B35=0,0,C35/B35) -> 0
A36: C. Homepage on-page | B36: =COUNTIF(Checklist!$D$7:$D$73,A36) -> 12 | C36: =COUNTIFS(Checklist!$D$7:$D$73,A36,Checklist!$L$7:$L$73,"Done") -> 0 | D36: =IF(B36=0,0,C36/B36) -> 0
A37: D. Structured data & entity | B37: =COUNTIF(Checklist!$D$7:$D$73,A37) -> 6 | C37: =COUNTIFS(Checklist!$D$7:$D$73,A37,Checklist!$L$7:$L$73,"Done") -> 0 | D37: =IF(B37=0,0,C37/B37) -> 0
A38: E. Evidence & credibility | B38: =COUNTIF(Checklist!$D$7:$D$73,A38) -> 5 | C38: =COUNTIFS(Checklist!$D$7:$D$73,A38,Checklist!$L$7:$L$73,"Done") -> 0 | D38: =IF(B38=0,0,C38/B38) -> 0
A39: F. Sample report | B39: =COUNTIF(Checklist!$D$7:$D$73,A39) -> 4 | C39: =COUNTIFS(Checklist!$D$7:$D$73,A39,Checklist!$L$7:$L$73,"Done") -> 0 | D39: =IF(B39=0,0,C39/B39) -> 0
A40: G. Technical & measurement | B40: =COUNTIF(Checklist!$D$7:$D$73,A40) -> 11 | C40: =COUNTIFS(Checklist!$D$7:$D$73,A40,Checklist!$L$7:$L$73,"Done") -> 0 | D40: =IF(B40=0,0,C40/B40) -> 0

Sheet Checklist
A1: novoseniorsafety.com: website change list (v2)
A2: Prepared 19 Sep 2026 from the homepage, Privacy, Terms and sample PDF as fetched. See the Verification sheet for what was and wasn't checked.
A3: How to use: edit only the yellow columns (Owner, Due date, Status, Notes). Filter the Batch column to see one work batch; work the batches in order. 'Depends on' lists item IDs to finish first; 'Done when' is the test for marking an A or B item Done. Status options: Not started / In progress / Blocked / Done. Example: Owner = Carl; Due date = 30 Sep 2026; Status = In progress; Notes = 'Lawyer reviewing Terms'.
A4: Priority: High = fix first (accuracy, trust, crawl access, core pages); Medium = next; Low = polish. Status is tracked only on this sheet; the Summary reads from it.
A6: ID | B6: Priority | C6: Batch | D6: Section | E6: Page / location | F6: Action | G6: Done when (A and B items) | H6: Why it matters | I6: Depends on | J6: Owner | K6: Due date | L6: Status | M6: Notes
A7: A1 | B7: High | C7: Batch 2 - Fix accuracy & credentials | D7: A. Accuracy & consistency | E7: Homepage FAQ + /terms.html | F7: Align payment terms. Homepage FAQ: payment in full by Interac e-Transfer at booking. Terms: due on report delivery; e-transfer, credit card or cheque. Pick one policy and state it identically in both places. | G7: FAQ and Terms state the same payment timing and methods; final wording is recorded on the Conflicts sheet; a lawyer has approved the Terms wording. | H7: Contradictory terms confuse customers; AI systems will quote whichever version they find, and a customer can hold you to the more favourable one. | L7: Not started
A8: A2 | B8: High | C8: Batch 2 - Fix accuracy & credentials | D8: A. Accuracy & consistency | E8: Homepage FAQ + /terms.html | F8: Align cancellation and no-show terms. FAQ: free over 24 h, 20% fee under 24 h, 20% kept on no-show. Terms: free over 48 h, 50% fee under 48 h, full fee on no-show. Choose one set. Have a lawyer review the final wording. | G8: FAQ and Terms give the same cancellation window, fee percentages and no-show fee; a lawyer has approved the wording. | H8: Same conflict as A1; cancellation fees are the most likely source of a dispute. | L8: Not started
A9: A3 | B9: High | C9: Batch 2 - Fix accuracy & credentials | D9: A. Accuracy & consistency | E9: Homepage FAQ + /terms.html | F9: Reconcile travel charges. FAQ: flat fee within 50 km of Calgary centre, and lists Airdrie, Cochrane, Okotoks etc. as standard area. Terms: a travel supplement may apply outside city limits. | G9: FAQ, pricing text and Terms describe the same service area and travel charges, so a customer in Airdrie or Okotoks gets the same answer from each. | H9: Customers in surrounding communities could be quoted differently from what the site promises. | L9: Not started
A10: A4 | B10: Medium | C10: Batch 2 - Fix accuracy & credentials | D10: A. Accuracy & consistency | E10: Homepage FAQ + /terms.html | F10: Align visit-length wording (homepage: about 1.5 h for a condo up to 3 h for a large home; Terms: 'two to three hours'). | G10: Homepage, Terms and the pricing page give the same visit-length range. | H10: Minor, but every factual mismatch weakens trust and citability. | L10: Not started
A11: A5 | B11: High | C11: Batch 2 - Fix accuracy & credentials | D11: A. Accuracy & consistency | E11: Homepage, sample PDF, /privacy.html | F11: Choose one accurate description of measuring equipment. Homepage: professional laser distance measurer, ±1.5 mm. Sample PDF methodology: measuring tape to the nearest millimetre plus a calibrated light meter. Privacy: LiDAR measurements. | G11: Measuring equipment is described identically on the homepage, methodology page/PDF and Privacy page, and matches what is actually used on visits. | H11: The site's headline differentiator (laser precision) is described three different ways. If the claim isn't accurate for every visit, remove or qualify it. | L11: Not started
A12: A6 | B12: High | C12: Batch 2 - Fix accuracy & credentials | D12: A. Accuracy & consistency | E12: Homepage, sample PDF (Section 10) | F12: Make contractor vetting criteria identical everywhere. Homepage: business registration, WCB, $2M insurance confirmed, 4.5+ Google rating (10+ reviews), intro call. PDF: business registration, WCB, prepaid contracting licence, $2M insurance, intro call, and tells the client to confirm insurance themselves. | G12: The vetting list is identical on the homepage, PDF Section 10 and the contractor-vetting page, and matches the checks actually performed. | H12: Homepage promises a rating check the PDF doesn't list, and 'insurance confirmed' conflicts with 'confirm it yourself'. | L12: Not started
A13: A7 | B13: Medium | C13: Batch 2 - Fix accuracy & credentials | D13: A. Accuracy & consistency | E13: Homepage, /privacy.html, /terms.html | F13: Use one contact email (homepage and PDF use info@; Privacy and Terms use carl@). | G13: One email address appears on every page and in the PDF. | H13: Consistency and entity clarity. | L13: Not started
A14: A8 | B14: High | C14: Batch 2 - Fix accuracy & credentials | D14: A. Accuracy & consistency | E14: Homepage funding section + FAQ | F14: Reword funding claims. Say the report identifies items that may qualify and that the client still needs contractor quotes or receipts. Remove 'provides the written cost estimates SHARP requires with every application' and 'provides the documentation the CRA requires'. | G14: Homepage funding section and FAQ no longer claim the report satisfies SHARP or CRA documentation requirements; wording says quotes or receipts are still needed; A17 is complete. | H14: Alberta.ca says SHARP needs a written cost estimate or receipts. Your own PDF calls its figures planning estimates, not quotes, and your Terms say the report is not a certification for any government program. (CRA receipt requirement is from general knowledge; confirm on canada.ca.) | I14: A17 | L14: Not started
A15: A9 | B15: High | C15: Batch 2 - Fix accuracy & credentials | D15: A. Accuracy & consistency | E15: Homepage About section, sample PDF Section 12 | F15: Describe SHSS accurately as an online course-based credential (17 modules per the issuer's course pages) rather than implying a licence. Avoid 'certified assessor' unless confirmed acceptable to the issuer. | G15: SHSS is described as a course-based credential everywhere it appears (homepage, PDF, Terms, About). | H15: Issuer and partner-college pages describe a self-paced online course (about 5 hours per one college partner). Readers who know the credential, such as occupational therapists, are likely to read this language closely. | L15: Not started
A16: A10 | B16: High | C16: Batch 2 - Fix accuracy & credentials | D16: A. Accuracy & consistency | E16: Homepage About section, sample PDF Section 12 | F16: Correct RHFAC wording. Remove 'Canada's leading accessibility rating credential' (no source) and the PDF statement that RHFAC is the basis for applying CSA/ASC B652:23 in a residential setting. Say instead that RHFAC Professional training covers rating the accessibility of buildings and sites, and that B652:23 is used as your reference for residential findings. | G16: No 'leading credential' or B652-basis claim remains on the homepage, PDF Section 12 or About; the replacement wording is in place. | H16: RHFAC Professional is an 8-week, roughly 60-hour course plus exam focused on rating buildings and sites, and RHFAC references CSA B651, not B652. No source found for the current claim. | L16: Not started
A17: A11 | B17: Medium | C17: Batch 2 - Fix accuracy & credentials | D17: A. Accuracy & consistency | E17: Sample PDF Section 12 | F17: Reword 'distributed in Canada through the Canadian Association of Occupational Therapists' so it doesn't read as an endorsement. | G17: The CAOT wording no longer reads as an endorsement. | H17: CAOT is one of several channels selling the course; its distributing the course is not an endorsement of your service. | L17: Not started
A18: A12 | B18: High | C18: Batch 2 - Fix accuracy & credentials | D18: A. Accuracy & consistency | E18: Homepage About section, planned /about | F18: Add verification: credential IDs or issuer verification links (SHSS, RHFAC), insurance amount with certificate on request, WCB status where applicable. | G18: Each credential has a verification link or ID on the site; insurance amount is stated; certificate is available on request; the documents are on file. | H18: Claims without verifiable proof are the weakest link for trust and AI citation. | L18: Not started
A19: A13 | B19: Medium | C19: Batch 2 - Fix accuracy & credentials | D19: A. Accuracy & consistency | E19: Homepage Measurement section + FAQ | F19: Change 'every specific finding is backed by a number' to 'every dimensional finding'. | G19: Wording changed on the homepage measurement section and the FAQ. | H19: The sample report contains many 'none present' findings that have no measurement. | I19: A5 | L19: Not started
A20: A14 | B20: High | C20: Batch 2 - Fix accuracy & credentials | D20: A. Accuracy & consistency | E20: /privacy.html | F20: Update the Privacy policy: (1) cover the quiz and 'email me my result & checklist' capture, including the dementia-diagnosis question and where answers are processed; (2) make the analytics statement match reality (see A16); (3) fix 'LiDAR' once A5 is settled; (4) get a legal review, including Canada's anti-spam law (CASL) for the checklist email. | G20: Policy covers the quiz and email capture, states analytics accurately, uses the final measuring wording; a lawyer has reviewed it, including anti-spam (CASL) consent. | H20: Policy says no marketing use and no analytics, but the site collects emails for a checklist. Not legal advice; needs a lawyer. | I20: A5, A16, G5 | L20: Not started
A21: A15 | B21: Medium | C21: Batch 2 - Fix accuracy & credentials | D21: A. Accuracy & consistency | E21: Homepage | F21: Add a short 'what this assessment is not' statement (not clinical or OT assessment, not a code inspection, not a contractor quote). | G21: A scope statement is visible on the homepage and consistent with the Terms. | H21: Currently only in the PDF and Terms; it should be visible where people decide. | L21: Not started
A22: A16 | B22: High | C22: Batch 1 - Verify & set up | D22: A. Accuracy & consistency | E22: Homepage source code | F22: View page source and confirm whether Google Analytics or Google Ads tags are present. Make the Privacy policy match. | G22: Page source checked; result recorded in Notes; Privacy policy matches (see A14). | H22: An outside audit claims GA/Ads tags exist; the Privacy policy says no analytics. One of them is wrong. | L22: Not started
A23: A17 | B23: Medium | C23: Batch 1 - Verify & set up | D23: A. Accuracy & consistency | E23: Homepage funding section, sample PDF Section 08 | F23: Verify AADL wording against alberta.ca: homepage says clinical assessment by an OT, PT or RN; PDF says typically OT. Confirm whether the hand-held shower and bath seat the PDF marks as likely AADL-eligible are actually on the benefits list. | G23: AADL wording checked against alberta.ca; homepage and PDF corrected if needed; result recorded in Notes. | H23: Not verified live; avoid promising coverage that isn't confirmed. | L23: Not started
A24: B1 | B24: High | C24: Batch 4 - New pages | D24: B. New pages & structure | E24: New page: funding guide | F24: Create the funding guide page (see 'New Pages' sheet, #1). | G24: Page live; every program figure checked against the official page on the publish date and dated on the page; linked from the homepage; in the sitemap. | H24: Funding questions are high-intent and citable; currently one section on the homepage. | I24: A8, A17 | L24: Not started
A25: B2 | B25: High | C25: Batch 4 - New pages | D25: B. New pages & structure | E25: New page: dementia assessment | F25: Create the dementia / Alzheimer's home safety page (#2). | G25: Page live and linked from the homepage; includes the scope statement; in the sitemap. | H25: Distinct search intent; currently a card and one FAQ answer. | I25: A15 | L25: Not started
A26: B3 | B26: High | C26: Batch 4 - New pages | D26: B. New pages & structure | E26: New page: fall risk | F26: Create the fall prevention / fall risk assessment page (#3). | G26: Page live; every statistic has a named primary source you have checked; linked from the homepage; in the sitemap. | H26: Core service query. | I26: E1 | L26: Not started
A27: B4 | B27: High | C27: Batch 4 - New pages | D27: B. New pages & structure | E27: New page: pricing | F27: Create the pricing page (#4), matching the corrected Terms. | G27: Page live; prices, payment, cancellation and travel match the corrected Terms word for word; in the sitemap. | H27: Pricing is already a strength; give it its own URL. | I27: A1, A2, A3, A4 | L27: Not started
A28: B5 | B28: Medium | C28: Batch 4 - New pages | D28: B. New pages & structure | E28: New page: about | F28: Create the About / credentials page (#5). | G28: Page live; credential wording matches A9/A10; verification links and insurance present; in the sitemap. | H28: Central to expertise and trust. | I28: A9, A10, A11, A12 | L28: Not started
A29: B6 | B29: Medium | C29: Batch 4 - New pages | D29: B. New pages & structure | E29: New page: sample report HTML | F29: Create an HTML 'what's inside a report' page (#6). | G29: Page live; figures match the PDF; PDF linked; placeholder contractors labelled; in the sitemap. | H29: Gives crawlers and AI extractable text instead of relying on the PDF. | I29: E2, F4 | L29: Not started
A30: B7 | B30: Medium | C30: Batch 4 - New pages | D30: B. New pages & structure | E30: New page: home safety vs OT | F30: Create the 'home safety assessment vs OT assessment' page (#7). | G30: Page live; Alberta health-system statements checked against official sources; in the sitemap. | H30: Answers a question families and OTs will ask; not addressed on the homepage. | I30: A15, A17 | L30: Not started
A31: B8 | B31: Medium | C31: Batch 4 - New pages | D31: B. New pages & structure | E31: New page: methodology | F31: Create the methodology page (#8): 12 categories, 143 checkpoints, ranking formula, B652:23 use. | G31: Page live; measuring description matches A5; ranking formula and B652:23 use explained; in the sitemap. | H31: The ranking formula appears only in the PDF and is a real differentiator. | I31: A5 | L31: Not started
A32: B9 | B32: Low | C32: Batch 4 - New pages | D32: B. New pages & structure | E32: New page: service areas | F32: Create one service-areas page (#9). Do not create a thin page per town. | G32: One page live; travel terms match Terms; no per-town duplicate pages. | H32: Thin near-duplicate pages can hurt. | I32: A3 | L32: Not started
A33: B10 | B33: Low | C33: Batch 4 - New pages | D33: B. New pages & structure | E33: New page: contractor vetting | F33: Create the contractor-vetting page (#10), matching A6. | G33: Page live; the checks listed match what is actually done (A6); in the sitemap. | H33: Supports the 'no referral fees' claim. | I33: A6 | L33: Not started
A34: B11 | B34: High | C34: Batch 4 - New pages | D34: B. New pages & structure | E34: Sitemap + homepage nav | F34: Add each new page to the sitemap and link to it from the homepage and footer; keep the homepage as the hub. | G34: Sitemap lists every live page; homepage and footer link to each; sitemap resubmitted in Search Console. | H34: Internal links show which topics you cover in depth. | I34: B1, B2, B3, B4, B5, B6, B7, B8, B9, B10 | L34: Not started
A35: B12 | B35: Medium | C35: Batch 3 - Homepage & site fixes | D35: B. New pages & structure | E35: Sitewide | F35: Pick one URL style: redirect /index.html to / (Privacy and Terms link to /index.html). | G35: /index.html redirects to /; all internal links point to /. | H35: Avoids duplicate URLs. | L35: Not started
A36: C1 | B36: High | C36: Batch 3 - Homepage & site fixes | D36: C. Homepage on-page | E36: Homepage | F36: Rewrite the H1 to include the service and place (e.g. 'Home safety assessments for seniors in Calgary'); keep 'Every risk found. Every fix prioritized.' as a subhead. | H36: Current H1 is a slogan with no topic or location. | L36: Not started
A37: C2 | B37: Medium | C37: Batch 3 - Homepage & site fixes | D37: C. Homepage on-page | E37: Homepage | F37: Make H2s descriptive (e.g. 'How much does a home safety assessment cost?' instead of 'Two focuses. One process.'). | H37: Clear headings help search engines and AI extract answers. | L37: Not started
A38: C3 | B38: High | C38: Batch 3 - Homepage & site fixes | D38: C. Homepage on-page | E38: Homepage (top) | F38: Add an 'at a glance' summary near the top: prices, delivery time, what is included, credentials, service area. | H38: Gives a quotable block for AI answers. | I38: A1, A2, A3, A4, A5 | L38: Not started
A39: C4 | B39: Medium | C39: Batch 3 - Homepage & site fixes | D39: C. Homepage on-page | E39: Homepage <head> | F39: Shorten the meta description to about 155 characters (currently about 255). | H39: Truncated in search results. | L39: Not started
A40: C5 | B40: Medium | C40: Batch 3 - Homepage & site fixes | D40: C. Homepage on-page | E40: Homepage quiz | F40: Fix literal '\u2014' characters showing in the quiz confirmation and 'skip ahead' text. Check in a browser. | H40: Visible encoding bug. | L40: Not started
A41: C6 | B41: Low | C41: Batch 3 - Homepage & site fixes | D41: C. Homepage on-page | E41: Homepage forms | F41: Stop hidden form-success messages appearing in the page's extracted text (inject on submit instead). | H41: Crawlers read 'We got your message' as page content. | L41: Not started
...

Sheet Conflicts
A1: Homepage / FAQ vs Terms, Privacy and sample PDF
A2: Decide the final wording in the yellow column, then make every location match. 'Checklist IDs' points to the items that carry out the change; track progress there, not here.
A4: Topic | B4: Homepage / FAQ says | C4: Terms, Privacy or sample PDF says | D4: Source of truth | E4: Checklist IDs | F4: Final wording to use
A5: Payment | B5: In full by Interac e-Transfer when you book; nothing billed after the visit. | C5: Terms: due on delivery of the report; e-transfer, credit card or cheque. | D5: Terms (legal document); other pages mirror it | E5: A1
A6: Cancellation | B6: Free up to 24 h before; under 24 h, 20% of fee plus GST kept. | C6: Terms: free with over 48 h notice; under 48 h, 50% of fee. | D6: Terms (legal document); other pages mirror it | E6: A2
A7: No-show | B7: 20% of fee plus GST kept. | C7: Terms: full fee applies. | D7: Terms (legal document); other pages mirror it | E7: A2
A8: Travel / service area | B8: Flat pricing within 50 km of Calgary centre; lists Airdrie, Cochrane, Chestermere, Okotoks and others as standard. | C8: Terms: travel supplement may apply outside Calgary city limits. | D8: Terms; pricing page mirrors it | E8: A3, B9
A9: Visit length | B9: About 1.5 h for a condo, up to 3 h for a large home. | C9: Terms: most visits two to three hours. Sample report: 125 minutes on site. | D9: Your actual visit times | E9: A4
A10: Measuring equipment | B10: Professional laser distance measurer, ±1.5 mm. | C10: Sample PDF: measuring tape to the nearest millimetre and a calibrated light meter. Privacy: LiDAR measurements and floor plan data. | D10: What is actually used on visits | E10: A5, A14
A11: Contractor vetting | B11: Registration, WCB, $2M insurance confirmed, 4.5+ Google rating (10+ reviews), intro call. | C11: PDF: registration, WCB, prepaid contracting licence, $2M insurance, intro call; Section 10 tells the client to confirm insurance themselves. | D11: The checks actually performed | E11: A6, B10
A12: Contact email | B12: info@novoseniorsafety.com | C12: Privacy and Terms: carl@novoseniorsafety.com | D12: Owner decision | E12: A7
A13: Funding paperwork | B13: Report provides the estimates SHARP requires and the documentation CRA requires. | C13: PDF: figures are planning estimates, not quotes. Terms: report is not a certification for any government program. Alberta.ca: SHARP needs a written estimate or receipts. | D13: alberta.ca / canada.ca for program rules; Terms for what the report is | E13: A8, A17, B1
A14: Analytics | B14: (An outside audit says Google Analytics/Ads tags are present; unverified.) | C14: Privacy: no cookies, tracking pixels or analytics; no Google Analytics. | D14: Actual page source | E14: A16, A14, G5

Sheet New Pages
A1: Planned new pages, in priority order
A2: Suggested URLs are proposals. Each page needs substantial original content; avoid thin or near-duplicate pages. Track status on the Checklist (IDs in column G), not here.
A4: Order | B4: Page | C4: Suggested URL | D4: Search intent it answers | E4: Content to include | F4: Caveats | G4: Checklist ID | H4: Depends on | I4: Notes
A5: 1 | B5: Funding guide | C5: /home-modification-funding-alberta | D5: SHARP Alberta; home accessibility tax credit; AADL; how to pay for home modifications | E5: Eligibility per program (SHARP: 65+, income $75,000 or less, 25% equity kept, loan max $40,000, grant income thresholds); what your report does and does not supply; primary-source links; 'verified on' date. Check whether RAMP (listed as related on the SHARP page) belongs here. | F5: Verify every figure live before publishing; program rules change. | G5: B1 | H5: A8, A17
A6: 2 | B6: Dementia / Alzheimer's home safety | C6: /alzheimers-dementia-home-safety-assessment | D6: Dementia home safety Calgary; wandering; stove safety | E6: Wandering and exit security, wayfinding, medication storage, kitchen hazards, what the assessment covers, example findings from the sample report, link to sample. | F6: Not a clinical assessment; keep the scope statement. | G6: B2 | H6: A15
A7: 3 | B7: Fall prevention / fall risk | C7: /fall-risk-assessment-calgary | D7: Fall risk assessment Calgary seniors; home hazards | E7: Common hazards by room, why measurements matter, how findings are prioritised, cited statistics. | F7: Verify and cite all statistics (E1). | G7: B3 | H7: E1
A8: 4 | B8: Pricing | C8: /pricing | D8: Home safety assessment cost Calgary | E8: Prices by home size, what is included, $195 reassessment, booking, payment and cancellation exactly as in the corrected Terms, service area. | F8: Must match Terms (see Conflicts sheet). | G8: B4 | H8: A1, A2, A3, A4
A9: 5 | B9: About / credentials | C9: /about | D9: Who is Carl Christie; is this assessor qualified | E9: Background, SHSS and RHFAC described accurately with verification links, insurance, method, photo. | F9: Wording per A9, A10, A12. | G9: B5 | H9: A9, A10, A11, A12
A10: 6 | B10: Sample report (HTML) | C10: /sample-report | D10: What is in a home safety report | E10: Key numbers (112 findings, 41 high priority), how findings are formatted, phased plan, PDF download link. | F10: Label placeholder contractor names. | G10: B6 | H10: E2, F4
A11: 7 | B11: Home safety assessment vs OT assessment | C11: /home-safety-assessment-vs-occupational-therapy | D11: Do I need an OT or a home safety assessment | E11: Differences, how they complement each other, AADL role of OTs, when to involve an OT. | F11: Verify Alberta health-system details before publishing. | G11: B7 | H11: A15, A17
A12: 8 | B12: Methodology | C12: /methodology | D12: How are home safety findings prioritised | E12: 12 categories, 143 checkpoints, ranking formula (checkpoint weight x severity divided by square root of cost), measurement, how CSA/ASC B652:23 is used and its limits. | F12: Must match A5 measuring wording. | G12: B8 | H12: A5
A13: 9 | B13: Service areas | C13: /service-areas | D13: Home safety assessment Airdrie, Cochrane, Okotoks | E13: Communities served, travel terms, how to confirm availability. | F13: One page only; no doorway pages. | G13: B9 | H13: A3
A14: 10 | B14: How we vet contractors | C14: /how-we-vet-contractors | D14: Trusted contractors for senior home modifications | E14: The checks you actually perform, no referral fees or commissions, how contractors are matched. | F14: Must match A6. | G14: B10 | H14: A6

Sheet Verification
A1: What was verified, what wasn't, and data still needed
A2: Enter a date in the yellow column whenever you (re)check an item. Funding figures and program rules change, so re-check them before publishing.
A3: Area | B3: Item | C3: Status | D3: Basis / how to check | E3: Date checked
A4: Crawl/access | B4: Homepage text is in the HTML (FAQ, pricing included) | C4: Verified | D4: Fetched homepage; content returned as text. | E4: 46284
A5: Crawl/access | B5: Title, canonical, robots meta (index, follow), Open Graph/Twitter tags, image alt text | C5: Verified | D5: Homepage metadata as fetched. | E5: 46284
A6: Facts | B6: SHARP figures in the sample PDF match Alberta.ca (loan max $40,000, income $75,000 or less, 25% equity, grant thresholds) | C6: Verified | D6: Alberta.ca SHARP page, fetched 19 Sep 2026. The homepage itself states no figures. | E6: 46284
A7: Facts | B7: CSA/ASC B652:23 exists and applies to new homes and alterations | C7: Verified | D7: CSA Group / SCC listings. | E7: 46284
A8: Credentials | B8: SHSS is an Age Safe online course (17 modules; about 5 hours per one college partner) | C8: Verified (issuer/partner pages) | D8: CAOT, Age Safe Canada, NACC, Mohawk pages. | E8: 46284
A9: Credentials | B9: RHFAC Professional is an 8-week, roughly 60-hour course plus exam for rating buildings and sites; RHFAC references CSA B651 | C9: Verified (issuer/provider pages) | D9: Rick Hansen Foundation, NSCC, AET pages. | E9: 46284
A10: Credentials | B10: Carl Christie's personal credentials, insurance and WCB status | C10: Not verified | D10: No public directory or certificate found; request documents.
A11: Crawl/access | B11: robots.txt | C11: Not verified | D11: Fetch tool could not open it. Open it yourself and check bot rules.
A12: Crawl/access | B12: sitemap.xml | C12: Not verified | D12: An outside audit says it lists three pages; unconfirmed.
A13: Crawl/access | B13: llms.txt | C13: Not verified | D13: Optional; low priority.
A14: Structured data | B14: JSON-LD (LocalBusiness, WebSite, FAQPage per outside audit) | C14: Not verified | D14: Scripts stripped from my extraction; use the Rich Results Test page.
A15: Privacy | B15: Google Analytics / Ads tags | C15: Conflicting | D15: Outside audit says present; Privacy policy says none. View page source.
A16: Technical | B16: Page speed, mobile rendering, redirects, colour contrast | C16: Not tested | D16: Run Lighthouse / PageSpeed Insights.
A17: Search presence | B17: Indexing status, rankings, backlinks, Google Business Profile | C17: Needs data | D17: Search Console, Bing Webmaster, backlink tool. One search for the brand/domain returned none of your pages (weak evidence).
A18: Funding | B18: AADL, HATC, MHRTC current rules and figures | C18: Not re-verified live | D18: Consistent with prior knowledge; check alberta.ca and canada.ca.
A19: Sample PDF | B19: Text layer quality (words ran together in my extraction) | C19: Needs testing | D19: pdftotext, copy-paste, screen reader.
A20: Data needed | B20: AI-citation test with 20-30 real queries across ChatGPT, Perplexity, Gemini, AI Overviews, Claude | C20: Needs data | D20: Manual logging; do a baseline before edits, then repeat quarterly.
A21: Data needed | B21: Real customer questions (call notes, form messages, OT/family questions) | C21: Needs data | D21: Prioritise new-page topics.
... A26: Assumption | B26: Sample report v3.1 is current and representative | C26: Assumed | D26: Stated on the sample itself.
